Workbook

Sheet combined_metrics
A1: seed | B1: timestamp | C1: model_name | D1: dataset_path | E1: learning_rate | F1: weight_decay | G1: batch_size | H1: num_train_epochs | I1: gradient_accumulation_steps | J1: eval_steps | K1: save_steps | L1: best_metric | M1: best_model_checkpoint | N1: global_step | O1: split | P1: eval_loss | Q1: eval_f1 | R1: eval_f1_ARTEFACT | S1: eval_f1_BIBL | T1: eval_f1_CONCEPT | U1: eval_f1_ORG | V1: eval_f1_PEOPLE | W1: eval_f1_PERSON | X1: eval_f1_PLACE | Y1: eval_precision | Z1: eval_precision_ARTEFACT | AA1: eval_precision_BIBL | AB1: eval_precision_CONCEPT | AC1: eval_precision_ORG | AD1: eval_precision_PEOPLE | AE1: eval_precision_PERSON | AF1: eval_precision_PLACE | AG1: eval_recall | AH1: eval_recall_ARTEFACT | AI1: eval_recall_BIBL | AJ1: eval_recall_CONCEPT | AK1: eval_recall_ORG | AL1: eval_recall_PEOPLE | AM1: eval_recall_PERSON | AN1: eval_recall_PLACE | AO1: eval_runtime | AP1: eval_samples_per_second | AQ1: eval_steps_per_second
A2: 42 | B2: 2026-02-26T10:37:51.232557 | C2: dbmdz/bert-base-german-cased | D2: /content/drive/MyDrive/ner_tei/hf_bert_base_cased | E2: 1e-05 | F2: 0.01 | G2: 16 | H2: 8 | I2: 2 | J2: 400 | K2: 400 | L2: 0.48751715 | M2: /content/drive/MyDrive/ner_tei/42/checkpoint-1600 | N2: 1992 | O2: test | P2: 0.63784498 | Q2: 0.44370335 | R2: 0.5076708507670852 | S2: 0.1153846153846153 | T2: 0.3569482288828337 | U2: 0.3720930232558139 | V2: 0.7699115044247786 | W2: 0.4042553191489361 | X2: 0.5824175824175823 | Y2: 0.51247249 | Z2: 0.51195499 | AA2: 0.43902439 | AB2: 0.46953405 | AC2: 0.66666667 | AD2: 0.75652174 | AE2: 0.4789916 | AF2: 0.58888889 | AG2: 0.39120694 | AH2: 0.50345781 | AI2: 0.066420664 | AJ2: 0.28791209 | AK2: 0.25806452 | AL2: 0.78378378 | AM2: 0.34969325 | AN2: 0.57608696 | AO2: 6.1685 | AP2: 293.265 | AQ2: 18.481
A3: 42 | B3: 2026-02-26T10:37:51.232557 | C3: dbmdz/bert-base-german-cased | D3: /content/drive/MyDrive/ner_tei/hf_bert_base_cased | E3: 1e-05 | F3: 0.01 | G3: 16 | H3: 8 | I3: 2 | J3: 400 | K3: 400 | L3: 0.48751715 | M3: /content/drive/MyDrive/ner_tei/42/checkpoint-1600 | N3: 1992 | O3: validation | P3: 0.6926338076591492 | Q3: 0.48607109 | R3: 0.5477419354838711 | S3: 0.1983471074380165 | T3: 0.3852813852813853 | U3: 0.4333333333333333 | V3: 0.6352941176470589 | W3: 0.5714285714285714 | X3: 0.7105263157894737 | Y3: 0.56563398 | Z3: 0.58031442 | AA3: 0.61538462 | AB3: 0.48108108 | AC3: 0.63414634 | AD3: 0.77142857 | AE3: 0.64893617 | AF3: 0.73636364 | AG3: 0.4261308950914341 | AH3: 0.51863164 | AI3: 0.1182266 | AJ3: 0.32129964 | AK3: 0.32911392 | AL3: 0.54 | AM3: 0.51046025 | AN3: 0.68644068 | AO3: 4.7747 | AP3: 318.135 | AQ3: 19.897
A4: 42 | B4: 2026-02-26T10:52:54.389065 | C4: dbmdz/bert-base-german-cased | D4: /content/drive/MyDrive/ner_tei/hf_bert_base_cased | E4: 2e-05 | F4: 0.01 | G4: 16 | H4: 8 | I4: 2 | J4: 400 | K4: 400 | L4: 0.5322223668793126 | M4: /content/drive/MyDrive/ner_tei/42/checkpoint-1600 | N4: 1992 | O4: test | P4: 0.6218276619911194 | Q4: 0.48591238 | R4: 0.5544024104452628 | S4: 0.2255639097744361 | T4: 0.4026294165981923 | U4: 0.4444444444444444 | V4: 0.7704918032786884 | W4: 0.44599303 | X4: 0.6096256684491979 | Y4: 0.5134039900249376 | Z4: 0.53731343 | AA4: 0.3515625 | AB4: 0.45837231 | AC4: 0.52173913 | AD4: 0.70676692 | AE4: 0.51612903 | AF4: 0.6 | AG4: 0.46121535 | AH4: 0.57261411 | AI4: 0.16605166 | AJ4: 0.35897436 | AK4: 0.38709677 | AL4: 0.84684685 | AM4: 0.39263804 | AN4: 0.61956522 | AO4: 6.0014 | AP4: 301.431 | AQ4: 18.996
A5: 42 | B5: 2026-02-26T10:52:54.389065 | C5: dbmdz/bert-base-german-cased | D5: /content/drive/MyDrive/ner_tei/hf_bert_base_cased | E5: 2e-05 | F5: 0.01 | G5: 16 | H5: 8 | I5: 2 | J5: 400 | K5: 400 | L5: 0.5322223668793126 | M5: /content/drive/MyDrive/ner_tei/42/checkpoint-1600 | N5: 1992 | O5: validation | P5: 0.6892657279968262 | Q5: 0.53203125 | R5: 0.5828182941903585 | S5: 0.2789115646258503 | T5: 0.4510406004776527 | U5: 0.5413533834586465 | V5: 0.7052631578947369 | W5: 0.5754060324825987 | X5: 0.7354838709677418 | Y5: 0.5797389330306469 | Z5: 0.58974359 | AA5: 0.45054945 | AB5: 0.52088258 | AC5: 0.66666667 | AD5: 0.74444444 | AE5: 0.64583333 | AF5: 0.74672489 | AG5: 0.4915784408084697 | AH5: 0.57605376 | AI5: 0.20197044 | AJ5: 0.3977136 | AK5: 0.4556962 | AL5: 0.67 | AM5: 0.51882845 | AN5: 0.72457627 | AO5: 4.7133 | AP5: 322.278 | AQ5: 20.156
A6: 42 | B6: 2026-02-26T13:45:46.295153 | C6: dbmdz/bert-base-german-cased | D6: /content/drive/MyDrive/ner_tei/hf_bert_base_cased | E6: 3e-05 | F6: 0.01 | G6: 16 | H6: 8 | I6: 2 | J6: 400 | K6: 400 | L6: 0.5456412889973038 | M6: /content/drive/MyDrive/ner_tei/42/checkpoint-1600 | N6: 1992 | O6: test | P6: 0.6443898677825928 | Q6: 0.5034152 | R6: 0.5749665327978581 | S6: 0.2803738317757009 | T6: 0.42273819 | U6: 0.4210526315789473 | V6: 0.7800829875518672 | W6: 0.4583333333333333 | X6: 0.5931758530183727 | Y6: 0.5232628398791541 | Z6: 0.55706874 | AA6: 0.38216561 | AB6: 0.46601942 | AC6: 0.46153846 | AD6: 0.72307692 | AE6: 0.528 | AF6: 0.57360406 | AG6: 0.4850182021842621 | AH6: 0.59405256 | AI6: 0.22140221 | AJ6: 0.38681319 | AK6: 0.38709677 | AL6: 0.84684685 | AM6: 0.40490798 | AN6: 0.61413043 | AO6: 5.8942 | AP6: 306.912 | AQ6: 19.341
A7: 42 | B7: 2026-02-26T13:45:46.295153 | C7: dbmdz/bert-base-german-cased | D7: /content/drive/MyDrive/ner_tei/hf_bert_base_cased | E7: 3e-05 | F7: 0.01 | G7: 16 | H7: 8 | I7: 2 | J7: 400 | K7: 400 | L7: 0.5456412889973038 | M7: /content/drive/MyDrive/ner_tei/42/checkpoint-1600 | N7: 1992 | O7: validation | P7: 0.7043734788894653 | Q7: 0.54608472 | R7: 0.5977791486736582 | S7: 0.3016393442622951 | T7: 0.4662698412698413 | U7: 0.5588235294117647 | V7: 0.7473684210526317 | W7: 0.5901639344262296 | X7: 0.7381974248927039 | Y7: 0.58530545 | Z7: 0.60373832 | AA7: 0.45098039 | AB7: 0.51762115 | AC7: 0.66666667 | AD7: 0.78888889 | AE7: 0.67021277 | AF7: 0.74782609 | AG7: 0.5117901828681425 | AH7: 0.59193647 | AI7: 0.22660099 | AJ7: 0.42418773 | AK7: 0.48101266 | AL7: 0.71 | AM7: 0.52719665 | AN7: 0.72881356 | AO7: 4.8691 | AP7: 311.966 | AQ7: 19.511
A8: 43 | B8: 2026-02-26T14:08:50.367393 | C8: dbmdz/bert-base-german-cased | D8: /content/drive/MyDrive/ner_tei/hf_bert_base_cased | E8: 1e-05 | F8: 0.01 | G8: 16 | H8: 8 | I8: 2 | J8: 400 | K8: 400 | L8: 0.4984818481848185 | M8: /content/drive/MyDrive/ner_tei/43/checkpoint-1600 | N8: 1992 | O8: test | P8: 0.6273161768913269 | Q8: 0.45946356 | R8: 0.5276653171390014 | S8: 0.1242236 | T8: 0.3812681309573145 | U8: 0.35 | V8: 0.7844827586206897 | W8: 0.3759398496240601 | X8: 0.58563536 | Y8: 0.5006605019815059 | Z8: 0.51515152 | AA8: 0.39215686 | AB8: 0.4389313 | AC8: 0.77777778 | AD8: 0.75206612 | AE8: 0.48543689 | AF8: 0.59550562 | AG8: 0.4245309437132455 | AH8: 0.54080221 | AI8: 0.073800738 | AJ8: 0.33699634 | AK8: 0.22580645 | AL8: 0.81981982 | AM8: 0.30674847 | AN8: 0.57608696 | AO8: 6.0151 | AP8: 300.741 | AQ8: 18.952
A9: 43 | B9: 2026-02-26T14:08:50.367393 | C9: dbmdz/bert-base-german-cased | D9: /content/drive/MyDrive/ner_tei/hf_bert_base_cased | E9: 1e-05 | F9: 0.01 | G9: 16 | H9: 8 | I9: 2 | J9: 400 | K9: 400 | L9: 0.4984818481848185 | M9: /content/drive/MyDrive/ner_tei/43/checkpoint-1600 | N9: 1992 | O9: validation | P9: 0.6629024147987366 | Q9: 0.49835027 | R9: 0.5562167240839336 | S9: 0.2096774193548387 | T9: 0.4141380460153384 | U9: 0.3818181818181818 | V9: 0.6586826347305389 | W9: 0.5615763546798029 | X9: 0.7180616740088106 | Y9: 0.55188541 | Z9: 0.57069409 | AA9: 0.57777778 | AB9: 0.4644727 | AC9: 0.67741935 | AD9: 0.82089552 | AE9: 0.68263473 | AF9: 0.74770642 | AG9: 0.4542829643888354 | AH9: 0.54245571 | AI9: 0.12807882 | AJ9: 0.37364621 | AK9: 0.26582278 | AL9: 0.55 | AM9: 0.47698745 | AN9: 0.69067797 | AO9: 4.9451 | AP9: 307.173 | AQ9: 19.211
A10: 43 | B10: 2026-02-26T14:39:24.183869 | C10: dbmdz/bert-base-german-cased | D10: /content/drive/MyDrive/ner_tei/hf_bert_base_cased | E10: 2e-05 | F10: 0.01 | G10: 16 | H10: 8 | I10: 2 | J10: 400 | K10: 400 | L10: 0.5277251484148036 | M10: /content/drive/MyDrive/ner_tei/43/checkpoint-1600 | N10: 1992 | O10: test | P10: 0.6308000683784485 | Q10: 0.48872288 | R10: 0.5520974289580515 | S10: 0.2376237623762375 | T10: 0.4227272727272727 | U10: 0.4137931034482758 | V10: 0.7673469387755102 | W10: 0.4397163120567376 | X10: 0.5904255319148937 | Y10: 0.5017699115044247 | Z10: 0.54039735 | AA10: 0.36090226 | AB10: 0.43764706 | AC10: 0.44444444 | AD10: 0.70149254 | AE10: 0.5210084 | AF10: 0.578125 | AG10: 0.4763371604592551 | AH10: 0.56431535 | AI10: 0.17712177 | AJ10: 0.40879121 | AK10: 0.38709677 | AL10: 0.84684685 | AM10: 0.3803681 | AN10: 0.60326087 | AO10: 6.087 | AP10: 297.193 | AQ10: 18.729
A11: 43 | B11: 2026-02-26T14:39:24.183869 | C11: dbmdz/bert-base-german-cased | D11: /content/drive/MyDrive/ner_tei/hf_bert_base_cased | E11: 2e-05 | F11: 0.01 | G11: 16 | H11: 8 | I11: 2 | J11: 400 | K11: 400 | L11: 0.5277251484148036 | M11: /content/drive/MyDrive/ner_tei/43/checkpoint-1600 | N11: 1992 | O11: validation | P11: 0.6621167063713074 | Q11: 0.52831143 | R11: 0.57917981 | S11: 0.2457337883959044 | T11: 0.4583977729662852 | U11: 0.5147058823529411 | V11: 0.71657754 | W11: 0.59207459 | X11: 0.7155172413793104 | Y11: 0.5564430244941427 | Z11: 0.59882583 | AA11: 0.4 | AB11: 0.47167409 | AC11: 0.61403509 | AD11: 0.77011494 | AE11: 0.66842105 | AF11: 0.72807018 | AG11: 0.5028873917228104 | AH11: 0.56078192 | AI11: 0.1773399 | AJ11: 0.44584838 | AK11: 0.44303797 | AL11: 0.67 | AM11: 0.53138075 | AN11: 0.70338983 | AO11: 4.9561 | AP11: 306.491 | AQ11: 19.168
A12: 43 | B12: 2026-02-26T14:48:34.946086 | C12: dbmdz/bert-base-german-cased | D12: /content/drive/MyDrive/ner_tei/hf_bert_base_cased | E12: 3e-05 | F12: 0.01 | G12: 16 | H12: 8 | I12: 2 | J12: 400 | K12: 400 | L12: 0.5375744519072362 | M12: /content/drive/MyDrive/ner_tei/43/checkpoint-1600 | N12: 1992 | O12: test | P12: 0.6717366576194763 | Q12: 0.4970111 | R12: 0.5545361875637106 | S12: 0.2716627634660422 | T12: 0.4406528189910978 | U12: 0.4727272727272728 | V12: 0.7510204081632653 | W12: 0.45614035 | X12: 0.5760000000000001 | Y12: 0.5053545586107091 | Z12: 0.54509018 | AA12: 0.37179487 | AB12: 0.44628099 | AC12: 0.54166667 | AD12: 0.68656716 | AE12: 0.53278689 | AF12: 0.56544503 | AG12: 0.4889386726407169 | AH12: 0.56431535 | AI12: 0.21402214 | AJ12: 0.43516484 | AK12: 0.41935484 | AL12: 0.82882883 | AM12: 0.39877301 | AN12: 0.58695652 | AO12: 6.0471 | AP12: 299.15 | AQ12: 18.852
A13: 43 | B13: 2026-02-26T14:48:34.946086 | C13: dbmdz/bert-base-german-cased | D13: /content/drive/MyDrive/ner_tei/hf_bert_base_cased | E13: 3e-05 | F13: 0.01 | G13: 16 | H13: 8 | I13: 2 | J13: 400 | K13: 400 | L13: 0.5375744519072362 | M13: /content/drive/MyDrive/ner_tei/43/checkpoint-1600 | N13: 1992 | O13: validation | P13: 0.6680243015289307 | Q13: 0.53703 | R13: 0.5837018319646241 | S13: 0.2912621359223301 | T13: 0.4708086169216359 | U13: 0.5255474452554744 | V13: 0.7301587301587302 | W13: 0.5910165484633569 | X13: 0.71186441 | Y13: 0.5666577611541544 | Z13: 0.60431655 | AA13: 0.4245283 | AB13: 0.48929267 | AC13: 0.62068966 | AD13: 0.7752809 | AE13: 0.67934783 | AF13: 0.71186441 | AG13: 0.5103464870067372 | AH13: 0.56444716 | AI13: 0.22167488 | AJ13: 0.45367028 | AK13: 0.4556962 | AL13: 0.69 | AM13: 0.52301255 | AN13: 0.71186441 | AO13: 4.7632 | AP13: 318.9 | AQ13: 19.944
A14: 42 | B14: 2026-02-26T20:40:52.246858 | C14: dbmdz/bert-base-german-uncased | D14: /content/drive/MyDrive/ner_tei/hf_bert_base_uncased | E14: 1e-05 | F14: 0.01 | G14: 16 | H14: 8 | I14: 2 | J14: 400 | K14: 400 | L14: 0.4817320703653585 | M14: /content/drive/MyDrive/ner_tei/42/checkpoint-1600 | N14: 1984 | O14: test | P14: 0.6791802644729614 | Q14: 0.43644717 | R14: 0.5000000000000001 | S14: 0.042553191 | T14: 0.3699273814609142 | U14: 0.2285714285714286 | V14: 0.6995073891625616 | W14: 0.38926174 | X14: 0.55585831 | Y14: 0.4799595823509599 | Z14: 0.48079385 | AA14: 0.4 | AB14: 0.44501542 | AC14: 1 | AD14: 0.76344086 | AE14: 0.42028986 | AF14: 0.55434783 | AG14: 0.4001684919966302 | AH14: 0.52080444 | AI14: 0.02247191 | AJ14: 0.31652047 | AK14: 0.12903226 | AL14: 0.64545455 | AM14: 0.3625 | AN14: 0.55737705 | AO14: 5.6164 | AP14: 321.025 | AQ14: 20.12
A15: 42 | B15: 2026-02-26T20:40:52.246858 | C15: dbmdz/bert-base-german-uncased | D15: /content/drive/MyDrive/ner_tei/hf_bert_base_uncased | E15: 1e-05 | F15: 0.01 | G15: 16 | H15: 8 | I15: 2 | J15: 400 | K15: 400 | L15: 0.4817320703653585 | M15: /content/drive/MyDrive/ner_tei/42/checkpoint-1600 | N15: 1984 | O15: validation | P15: 0.7246914505958557 | Q15: 0.48173207 | R15: 0.5559385772485115 | S15: 0.046728972 | T15: 0.39915523 | U15: 0.15909091 | V15: 0.5599999999999999 | W15: 0.5462962962962962 | X15: 0.64978903 | Y15: 0.5521091811414393 | Z15: 0.57225806 | AA15: 0.45454545 | AB15: 0.48050847 | AC15: 0.875 | AD15: 0.84 | AE15: 0.62433862 | AF15: 0.65254237 | AG15: 0.4272683629380701 | AH15: 0.54052407 | AI15: 0.024630542 | AJ15: 0.34136063 | AK15: 0.0875 | AL15: 0.42 | AM15: 0.48559671 | AN15: 0.64705882 | AO15: 4.6698 | AP15: 324.85 | AQ15: 20.343
A16: 42 | B16: 2026-03-02T11:15:47.554330 | C16: dbmdz/bert-base-german-uncased | D16: /content/drive/MyDrive/ner_tei/hf_bert_base_uncased | E16: 2e-05 | F16: 0.01 | G16: 16 | H16: 8 | I16: 2 | J16: 400 | K16: 400 | L16: 0.5325961167545326 | M16: /content/drive/MyDrive/ner_tei/42/checkpoint-1600 | N16: 1984 | O16: test | P16: 0.6880733370780945 | Q16: 0.49097163 | R16: 0.5426052889324191 | S16: 0.1712707182320442 | T16: 0.4432432432432432 | U16: 0.4583333333333333 | V16: 0.7914893617021277 | W16: 0.4452054794520548 | X16: 0.5567010309278351 | Y16: 0.5013169446883231 | Z16: 0.51264651 | AA16: 0.32631579 | AB16: 0.46972177 | AC16: 0.64705882 | AD16: 0.744 | AE16: 0.49242424 | AF16: 0.52682927 | AG16: 0.48104465 | AH16: 0.57628294 | AI16: 0.11610487 | AJ16: 0.41959064 | AK16: 0.35483871 | AL16: 0.84545455 | AM16: 0.40625 | AN16: 0.59016393 | AO16: 6.1453 | AP16: 293.393 | AQ16: 18.388
A17: 42 | B17: 2026-03-02T11:15:47.554330 | C17: dbmdz/bert-base-german-uncased | D17: /content/drive/MyDrive/ner_tei/hf_bert_base_uncased | E17: 2e-05 | F17: 0.01 | G17: 16 | H17: 8 | I17: 2 | J17: 400 | K17: 400 | L17: 0.5325961167545326 | M17: /content/drive/MyDrive/ner_tei/42/checkpoint-1600 | N17: 1984 | O17: validation | P17: 0.6962987184524536 | Q17: 0.53347038 | R17: 0.5942786834820056 | S17: 0.2037735849056604 | T17: 0.4518883415435139 | U17: 0.4285714285714286 | V17: 0.7222222222222223 | W17: 0.61111111 | X17: 0.7066115702479339 | Y17: 0.5739563173901023 | Z17: 0.6 | AA17: 0.43548387 | AB17: 0.49710983 | AC17: 0.58695652 | AD17: 0.8125 | AE17: 0.6984127 | AF17: 0.69512195 | AG17: 0.4983197311569851 | AH17: 0.58866545 | AI17: 0.13300493 | AJ17: 0.41420831 | AK17: 0.3375 | AL17: 0.65 | AM17: 0.54320988 | AN17: 0.71848739 | AO17: 4.7355 | AP17: 320.347 | AQ17: 20.061
A18: 42 | B18: 2026-03-02T11:34:02.039800 | C18: dbmdz/bert-base-german-uncased | D18: /content/drive/MyDrive/ner_tei/hf_bert_base_uncased | E18: 3e-05 | F18: 0.01 | G18: 16 | H18: 8 | I18: 2 | J18: 400 | K18: 400 | L18: 0.5485944787596118 | M18: /content/drive/MyDrive/ner_tei/42/checkpoint-1600 | N18: 1984 | O18: test | P18: 0.6686637997627258 | Q18: 0.5009004 | R18: 0.5578673602080624 | S18: 0.2188295165394402 | T18: 0.4475574712643678 | U18: 0.4347826086956521 | V18: 0.7594936708860759 | W18: 0.4733333333333333 | X18: 0.5900783289817232 | Y18: 0.4942591580098414 | Z18: 0.5250918 | AA18: 0.34126984 | AB18: 0.43997175 | AC18: 0.66666667 | AD18: 0.70866142 | AE18: 0.50714286 | AF18: 0.565 | AG18: 0.50772255 | AH18: 0.59500693 | AI18: 0.16104869 | AJ18: 0.45540936 | AK18: 0.32258065 | AL18: 0.81818182 | AM18: 0.44375 | AN18: 0.61748634 | AO18: 6.0195 | AP18: 299.527 | AQ18: 18.772
A19: 42 | B19: 2026-03-02T11:34:02.039800 | C19: dbmdz/bert-base-german-uncased | D19: /content/drive/MyDrive/ner_tei/hf_bert_base_uncased | E19: 3e-05 | F19: 0.01 | G19: 16 | H19: 8 | I19: 2 | J19: 400 | K19: 400 | L19: 0.5485944787596118 | M19: /content/drive/MyDrive/ner_tei/42/checkpoint-1600 | N19: 1984 | O19: validation | P19: 0.6881030201911926 | Q19: 0.5477482 | R19: 0.6029684601113173 | S19: 0.2635135135135135 | T19: 0.4744687599111957 | U19: 0.4962406015037593 | V19: 0.7195767195767195 | W19: 0.5995423340961098 | X19: 0.7298969072164948 | Y19: 0.5772400957192236 | Z19: 0.61205273 | AA19: 0.41935484 | AB19: 0.50134048 | AC19: 0.62264151 | AD19: 0.76404494 | AE19: 0.67525773 | AF19: 0.71659919 | AG19: 0.5211233797407585 | AH19: 0.59414991 | AI19: 0.19211823 | AJ19: 0.45033113 | AK19: 0.4125 | AL19: 0.68 | AM19: 0.53909465 | AN19: 0.74369748 | AO19: 4.7344 | AP19: 320.422 | AQ19: 20.066
A20: 43 | B20: 2026-03-02T11:53:17.308050 | C20: dbmdz/bert-base-german-uncased | D20: /content/drive/MyDrive/ner_tei/hf_bert_base_uncased | E20: 1e-05 | F20: 0.01 | G20: 16 | H20: 8 | I20: 2 | J20: 400 | K20: 400 | L20: 0.4841845816787621 | M20: /content/drive/MyDrive/ner_tei/43/checkpoint-1600 | N20: 1984 | O20: test | P20: 0.6624618172645569 | Q20: 0.43894081 | R20: 0.5117565698478562 | S20: 0.041666667 | T20: 0.3585623678646934 | U20: 0.2105263157894737 | V20: 0.7685185185185186 | W20: 0.3878326996197718 | X20: 0.5642458100558659 | Y20: 0.4928296607205316 | Z20: 0.51034483 | AA20: 0.28571429 | AB20: 0.42527583 | AC20: 0.57142857 | AD20: 0.78301887 | AE20: 0.49514563 | AF20: 0.57714286 | AG20: 0.3956753720864925 | AH20: 0.51317614 | AI20: 0.02247191 | AJ20: 0.30994152 | AK20: 0.12903226 | AL20: 0.75454545 | AM20: 0.31875 | AN20: 0.55191257 | AO20: 6.0368 | AP20: 298.666 | AQ20: 18.718
A21: 43 | B21: 2026-03-02T11:53:17.308050 | C21: dbmdz/bert-base-german-uncased | D21: /content/drive/MyDrive/ner_tei/hf_bert_base_uncased | E21: 1e-05 | F21: 0.01 | G21: 16 | H21: 8 | I21: 2 | J21: 400 | K21: 400 | L21: 0.4841845816787621 | M21: /content/drive/MyDrive/ner_tei/43/checkpoint-1600 | N21: 1984 | O21: validation | P21: 0.7109706401824951 | Q21: 0.4844414 | R21: 0.5573135292218275 | S21: 0.082568807 | T21: 0.3939712583245706 | U21: 0.1935483870967742 | V21: 0.6419753086419753 | W21: 0.5525672371638142 | X21: 0.6868250539956803 | Y21: 0.5647171620325983 | Z21: 0.59271978 | AA21: 0.6 | AB21: 0.47147651 | AC21: 0.69230769 | AD21: 0.83870968 | AE21: 0.68072289 | AF21: 0.70666667 | AG21: 0.4241478636581853 | AH21: 0.52589884 | AI21: 0.044334975 | AJ21: 0.33835039 | AK21: 0.1125 | AL21: 0.52 | AM21: 0.46502058 | AN21: 0.66806723 | AO21: 4.8622 | AP21: 311.999 | AQ21: 19.538
A22: 43 | B22: 2026-03-02T12:03:54.402835 | C22: dbmdz/bert-base-german-uncased | D22: /content/drive/MyDrive/ner_tei/hf_bert_base_uncased | E22: 2e-05 | F22: 0.01 | G22: 16 | H22: 8 | I22: 2 | J22: 400 | K22: 400 | L22: 0.5305857957490928 | M22: /content/drive/MyDrive/ner_tei/43/checkpoint-1600 | N22: 1984 | O22: test | P22: 0.6356234550476074 | Q22: 0.48371146 | R22: 0.5494355114608279 | S22: 0.1889763779527559 | T22: 0.4212121212121212 | U22: 0.3846153846153846 | V22: 0.7811158798283262 | W22: 0.4306569343065694 | X22: 0.57908847 | Y22: 0.50165913 | Z22: 0.54220122 | AA22: 0.31578947 | AB22: 0.43710692 | AC22: 0.47619048 | AD22: 0.7398374 | AE22: 0.51754386 | AF22: 0.56842105 | AG22: 0.46700365 | AH22: 0.55686546 | AI22: 0.13483146 | AJ22: 0.40643275 | AK22: 0.32258065 | AL22: 0.82727273 | AM22: 0.36875 | AN22: 0.59016393 | AO22: 6.2962 | AP22: 286.364 | AQ22: 17.947
A23: 43 | B23: 2026-03-02T12:03:54.402835 | C23: dbmdz/bert-base-german-uncased | D23: /content/drive/MyDrive/ner_tei/hf_bert_base_uncased | E23: 2e-05 | F23: 0.01 | G23: 16 | H23: 8 | I23: 2 | J23: 400 | K23: 400 | L23: 0.5305857957490928 | M23: /content/drive/MyDrive/ner_tei/43/checkpoint-1600 | N23: 1984 | O23: validation | P23: 0.6861404776573181 | Q23: 0.5305383 | R23: 0.5876716703928457 | S23: 0.2323943661971831 | T23: 0.4480414373583684 | U23: 0.4776119402985075 | V23: 0.7379679144385026 | W23: 0.5882352941176471 | X23: 0.7489539748953975 | Y23: 0.5755193711398091 | Z23: 0.61744966 | AA23: 0.40740741 | AB23: 0.48459384 | AC23: 0.59259259 | AD23: 0.79310345 | AE23: 0.68681319 | AF23: 0.74583333 | AG23: 0.4920787325972156 | AH23: 0.56063376 | AI23: 0.16256158 | AJ23: 0.4166165 | AK23: 0.4 | AL23: 0.69 | AM23: 0.51440329 | AN23: 0.75210084 | AO23: 4.7855 | AP23: 317.001 | AQ23: 19.852
A24: 43 | B24: 2026-03-02T12:11:09.913190 | C24: dbmdz/bert-base-german-uncased | D24: /content/drive/MyDrive/ner_tei/hf_bert_base_uncased | E24: 3e-05 | F24: 0.01 | G24: 16 | H24: 8 | I24: 2 | J24: 400 | K24: 400 | L24: 0.5391639871382636 | M24: /content/drive/MyDrive/ner_tei/43/checkpoint-1600 | N24: 1984 | O24: test | P24: 0.6300866007804871 | Q24: 0.49756517 | R24: 0.5708390646492434 | S24: 0.2281553398058252 | T24: 0.4306326304106548 | U24: 0.3793103448275862 | V24: 0.7679324894514767 | W24: 0.4555160142348755 | X24: 0.5848563968668408 | Y24: 0.50774627 | Z24: 0.56616644 | AA24: 0.32413793 | AB24: 0.43595506 | AC24: 0.40740741 | AD24: 0.71653543 | AE24: 0.52892562 | AF24: 0.56 | AG24: 0.4877843302443134 | AH24: 0.57558946 | AI24: 0.17602996 | AJ24: 0.4254386 | AK24: 0.35483871 | AL24: 0.82727273 | AM24: 0.4 | AN24: 0.61202186 | AO24: 5.8282 | AP24: 309.359 | AQ24: 19.389
A25: 43 | B25: 2026-03-02T12:11:09.913190 | C25: dbmdz/bert-base-german-uncased | D25: /content/drive/MyDrive/ner_tei/hf_bert_base_uncased | E25: 3e-05 | F25: 0.01 | G25: 16 | H25: 8 | I25: 2 | J25: 400 | K25: 400 | L25: 0.5391639871382636 | M25: /content/drive/MyDrive/ner_tei/43/checkpoint-1600 | N25: 1984 | O25: validation | P25: 0.6913864016532898 | Q25: 0.53911477 | R25: 0.5956620265458077 | S25: 0.2466666666666666 | T25: 0.4617834394904458 | U25: 0.4962406015037593 | V25: 0.71134021 | W25: 0.6041189931350115 | X25: 0.7473903966597077 | Y25: 0.5809761508596784 | Z25: 0.63535912 | AA25: 0.3814433 | AB25: 0.49019608 | AC25: 0.62264151 | AD25: 0.73404255 | AE25: 0.68041237 | AF25: 0.74273859 | AG25: 0.5028804608737398 | AH25: 0.56063376 | AI25: 0.18226601 | AJ25: 0.43648405 | AK25: 0.4125 | AL25: 0.69 | AM25: 0.54320988 | AN25: 0.75210084 | AO25: 4.8231 | AP25: 314.529 | AQ25: 19.697
A26: 42 | B26: 2026-02-26T15:01:08.957471 | C26: deepset/gbert-base | D26: /content/drive/MyDrive/ner_tei/hf_gbert_base | E26: 1e-05 | F26: 0.01 | G26: 16 | H26: 8 | I26: 2 | J26: 400 | K26: 400 | L26: 0.4856601731601731 | M26: /content/drive/MyDrive/ner_tei/42/checkpoint-1600 | N26: 1992 | O26: test | P26: 0.6709668636322021 | Q26: 0.43725311 | R26: 0.5118136439267886 | S26: 0.079470199 | T26: 0.3448275862068965 | U26: 0.1951219512195122 | V26: 0.7478260869565216 | W26: 0.4275862068965517 | X26: 0.5714285714285715 | Y26: 0.4779143141813351 | Z26: 0.49326491 | AA26: 0.38709677 | AB26: 0.4047384 | AC26: 0.4 | AD26: 0.72268908 | AE26: 0.48818898 | AF26: 0.63157895 | AG26: 0.4029683562027443 | AH26: 0.53181189 | AI26: 0.044280443 | AJ26: 0.3003663 | AK26: 0.12903226 | AL26: 0.77477477 | AM26: 0.3803681 | AN26: 0.52173913 | AO26: 5.686 | AP26: 318.15 | AQ26: 20.049
A27: 42 | B27: 2026-02-26T15:01:08.957471 | C27: deepset/gbert-base | D27: /content/drive/MyDrive/ner_tei/hf_gbert_base | E27: 1e-05 | F27: 0.01 | G27: 16 | H27: 8 | I27: 2 | J27: 400 | K27: 400 | L27: 0.4856601731601731 | M27: /content/drive/MyDrive/ner_tei/42/checkpoint-1600 | N27: 1992 | O27: validation | P27: 0.7175308465957642 | Q27: 0.48634766 | R27: 0.5620873939012888 | S27: 0.098214286 | T27: 0.3941299790356394 | U27: 0.2417582417582417 | V27: 0.6936416184971099 | W27: 0.5217391304347826 | X27: 0.6666666666666666 | Y27: 0.5549043800123381 | Z27: 0.57901554 | AA27: 0.52380952 | AB27: 0.47 | AC27: 0.91666667 | AD27: 0.82191781 | AE27: 0.61714286 | AF27: 0.69585253 | AG27: 0.4328681424446583 | AH27: 0.54612095 | AI27: 0.054187192 | AJ27: 0.33935018 | AK27: 0.13924051 | AL27: 0.6 | AM27: 0.45188285 | AN27: 0.63983051 | AO27: 4.7164 | AP27: 322.07 | AQ27: 20.143
A28: 42 | B28: 2026-02-26T15:12:06.392309 | C28: deepset/gbert-base | D28: /content/drive/MyDrive/ner_tei/hf_gbert_base | E28: 2e-05 | F28: 0.01 | G28: 16 | H28: 8 | I28: 2 | J28: 400 | K28: 400 | L28: 0.5169513797634692 | M28: /content/drive/MyDrive/ner_tei/42/checkpoint-1600 | N28: 1992 | O28: test | P28: 0.6649791598320007 | Q28: 0.47085002 | R28: 0.5338809034907598 | S28: 0.2383419689119171 | T28: 0.3936 | U28: 0.4137931034482758 | V28: 0.7606837606837608 | W28: 0.4482758620689655 | X28: 0.58689459 | Y28: 0.5006309148264985 | Z28: 0.52845528 | AA28: 0.4 | AB28: 0.43348018 | AC28: 0.44444444 | AD28: 0.72357724 | AE28: 0.51181102 | AF28: 0.61676647 | AG28: 0.4444133295995519 | AH28: 0.53941909 | AI28: 0.1697417 | AJ28: 0.36043956 | AK28: 0.38709677 | AL28: 0.8018018 | AM28: 0.39877301 | AN28: 0.55978261 | AO28: 6.3254 | AP28: 285.991 | AQ28: 18.023
A29: 42 | B29: 2026-02-26T15:12:06.392309 | C29: deepset/gbert-base | D29: /content/drive/MyDrive/ner_tei/hf_gbert_base | E29: 2e-05 | F29: 0.01 | G29: 16 | H29: 8 | I29: 2 | J29: 400 | K29: 400 | L29: 0.5169513797634692 | M29: /content/drive/MyDrive/ner_tei/42/checkpoint-1600 | N29: 1992 | O29: validation | P29: 0.71154839 | Q29: 0.51706933 | R29: 0.58290816 | S29: 0.3024055 | T29: 0.42003339 | U29: 0.5112781954887219 | V29: 0.7374301675977653 | W29: 0.5767441860465117 | X29: 0.6991150442477877 | Y29: 0.5690751445086705 | Z29: 0.60973983 | AA29: 0.5 | AB29: 0.47186797 | AC29: 0.62962963 | AD29: 0.83544304 | AE29: 0.64921466 | AF29: 0.73148148 | AG29: 0.4737728585178056 | AH29: 0.55833842 | AI29: 0.21674877 | AJ29: 0.37845969 | AK29: 0.43037975 | AL29: 0.66 | AM29: 0.51882845 | AN29: 0.66949153 | AO29: 4.8625 | AP29: 312.39 | AQ29: 19.537
A30: 42 | B30: 2026-02-26T15:26:31.826051 | C30: deepset/gbert-base | D30: /content/drive/MyDrive/ner_tei/hf_gbert_base | E30: 3e-05 | F30: 0.01 | G30: 16 | H30: 8 | I30: 2 | J30: 400 | K30: 400 | L30: 0.5237717908082408 | M30: /content/drive/MyDrive/ner_tei/42/checkpoint-1200 | N30: 1992 | O30: test | P30: 0.6661579012870789 | Q30: 0.47925436 | R30: 0.5355113636363636 | S30: 0.2939759036144578 | T30: 0.4072289156626506 | U30: 0.4285714285714285 | V30: 0.7521367521367521 | W30: 0.4657534246575342 | X30: 0.5959885386819485 | Y30: 0.5173644920480364 | Z30: 0.55036496 | AA30: 0.42361111 | AB30: 0.45066667 | AC30: 0.48 | AD30: 0.71544715 | AE30: 0.52713178 | AF30: 0.63030303 | AG30: 0.4463735648277793 | AH30: 0.52143845 | AI30: 0.22509225 | AJ30: 0.37142857 | AK30: 0.38709677 | AL30: 0.79279279 | AM30: 0.41717791 | AN30: 0.56521739 | AO30: 5.9088 | AP30: 306.151 | AQ30: 19.293
A31: 42 | B31: 2026-02-26T15:26:31.826051 | C31: deepset/gbert-base | D31: /content/drive/MyDrive/ner_tei/hf_gbert_base | E31: 3e-05 | F31: 0.01 | G31: 16 | H31: 8 | I31: 2 | J31: 400 | K31: 400 | L31: 0.5237717908082408 | M31: /content/drive/MyDrive/ner_tei/42/checkpoint-1200 | N31: 1992 | O31: validation | P31: 0.7195955514907837 | Q31: 0.52455121 | R31: 0.5809399477806789 | S31: 0.3344262295081967 | T31: 0.4374999999999999 | U31: 0.5223880597014925 | V31: 0.7362637362637363 | W31: 0.5931034482758621 | X31: 0.7008928571428571 | Y31: 0.5809941520467836 | Z31: 0.62368605 | AA31: 0.5 | AB31: 0.48885587 | AC31: 0.63636364 | AD31: 0.81707317 | AE31: 0.65816327 | AF31: 0.74056604 | AG31: 0.4781039461020211 | AH31: 0.54367746 | AI31: 0.25123153 | AJ31: 0.39590854 | AK31: 0.44303797 | AL31: 0.67 | AM31: 0.53974895 | AN31: 0.66525424 | AO31: 4.7923 | AP31: 316.967 | AQ31: 19.823
A32: 43 | B32: 2026-02-26T15:37:03.441751 | C32: deepset/gbert-base | D32: /content/drive/MyDrive/ner_tei/hf_gbert_base | E32: 1e-05 | F32: 0.01 | G32: 16 | H32: 8 | I32: 2 | J32: 400 | K32: 400 | L32: 0.5047619047619047 | M32: /content/drive/MyDrive/ner_tei/43/checkpoint-1600 | N32: 1992 | O32: test | P32: 0.6131545305252075 | Q32: 0.44807165 | R32: 0.5184472248957331 | S32: 0.1042345276872964 | T32: 0.3644752018454441 | U32: 0.3 | V32: 0.7627118644067797 | W32: 0.3971119133574007 | X32: 0.5913043478260869 | Y32: 0.46270883 | Z32: 0.48354279 | AA32: 0.44444444 | AB32: 0.38349515 | AC32: 0.66666667 | AD32: 0.72 | AE32: 0.48245614 | AF32: 0.63354037 | AG32: 0.4343321198543825 | AH32: 0.55878285 | AI32: 0.05904059 | AJ32: 0.34725275 | AK32: 0.19354839 | AL32: 0.81081081 | AM32: 0.33742331 | AN32: 0.55434783 | AO32: 6.0826 | AP32: 297.407 | AQ32: 18.742
A33: 43 | B33: 2026-02-26T15:37:03.441751 | C33: deepset/gbert-base | D33: /content/drive/MyDrive/ner_tei/hf_gbert_base | E33: 1e-05 | F33: 0.01 | G33: 16 | H33: 8 | I33: 2 | J33: 400 | K33: 400 | L33: 0.5047619047619047 | M33: /content/drive/MyDrive/ner_tei/43/checkpoint-1600 | N33: 1992 | O33: validation | P33: 0.6722208261489868 | Q33: 0.50418222 | R33: 0.5850837138508372 | S33: 0.1298701298701298 | T33: 0.4150462225055786 | U33: 0.3137254901960784 | V33: 0.7045454545454546 | W33: 0.5124378109452736 | X33: 0.6894977168949771 | Y33: 0.54190871 | Z33: 0.58313107 | AA33: 0.53571429 | AB33: 0.44135593 | AC33: 0.69565217 | AD33: 0.81578947 | AE33: 0.63190184 | AF33: 0.74752475 | AG33: 0.4713666987487969 | AH33: 0.58704948 | AI33: 0.073891626 | AJ33: 0.39169675 | AK33: 0.20253165 | AL33: 0.62 | AM33: 0.43096234 | AN33: 0.63983051 | AO33: 4.944 | AP33: 307.244 | AQ33: 19.215
A34: 43 | B34: 2026-02-26T15:44:57.672387 | C34: deepset/gbert-base | D34: /content/drive/MyDrive/ner_tei/hf_gbert_base | E34: 2e-05 | F34: 0.01 | G34: 16 | H34: 8 | I34: 2 | J34: 400 | K34: 400 | L34: 0.5296052631578947 | M34: /content/drive/MyDrive/ner_tei/43/checkpoint-1600 | N34: 1992 | O34: test | P34: 0.5947195291519165 | Q34: 0.48623199 | R34: 0.5449664429530201 | S34: 0.2821782178217822 | T34: 0.4138702460850111 | U34: 0.2857142857142857 | V34: 0.7679324894514767 | W34: 0.4668989547038327 | X34: 0.6280991735537189 | Y34: 0.4956369982547993 | Z34: 0.52933507 | AA34: 0.42857143 | AB34: 0.4214123 | AC34: 0.32 | AD34: 0.72222222 | AE34: 0.54032258 | AF34: 0.63687151 | AG34: 0.4771772612713525 | AH34: 0.5615491 | AI34: 0.2103321 | AJ34: 0.40659341 | AK34: 0.25806452 | AL34: 0.81981982 | AM34: 0.41104294 | AN34: 0.61956522 | AO34: 5.912 | AP34: 305.99 | AQ34: 19.283
A35: 43 | B35: 2026-02-26T15:44:57.672387 | C35: deepset/gbert-base | D35: /content/drive/MyDrive/ner_tei/hf_gbert_base | E35: 2e-05 | F35: 0.01 | G35: 16 | H35: 8 | I35: 2 | J35: 400 | K35: 400 | L35: 0.5296052631578947 | M35: /content/drive/MyDrive/ner_tei/43/checkpoint-1600 | N35: 1992 | O35: validation | P35: 0.6872565150260925 | Q35: 0.52944902 | R35: 0.6080150281778335 | S35: 0.2828947368421052 | T35: 0.4321796071094481 | U35: 0.5797101449275363 | V35: 0.7111111111111111 | W35: 0.5734939759036144 | X35: 0.7002188183807438 | Y35: 0.5589729874297941 | Z35: 0.6236352 | AA35: 0.42574257 | AB35: 0.44854369 | AC35: 0.6779661 | AD35: 0.8 | AE35: 0.67613636 | AF35: 0.7239819 | AG35: 0.5028873917228104 | AH35: 0.59315822 | AI35: 0.21182266 | AJ35: 0.41696751 | AK35: 0.50632911 | AL35: 0.64 | AM35: 0.49790795 | AN35: 0.6779661 | AO35: 5.0996 | AP35: 297.864 | AQ35: 18.629
A36: 43 | B36: 2026-02-26T17:11:32.953489 | C36: deepset/gbert-base | D36: /content/drive/MyDrive/ner_tei/hf_gbert_base | E36: 3e-05 | F36: 0.01 | G36: 16 | H36: 8 | I36: 2 | J36: 400 | K36: 400 | L36: 0.5337802991232594 | M36: /content/drive/MyDrive/ner_tei/43/checkpoint-1600 | N36: 1992 | O36: test | P36: 0.6163932681083679 | Q36: 0.49346546 | R36: 0.5481886534518114 | S36: 0.3198198198198199 | T36: 0.42109256 | U36: 0.40625 | V36: 0.7457627118644067 | W36: 0.4913494809688581 | X36: 0.6413043478260869 | Y36: 0.5064858490566038 | Z36: 0.54189189 | AA36: 0.41040462 | AB36: 0.43666404 | AC36: 0.39393939 | AD36: 0.704 | AE36: 0.56349206 | AF36: 0.64130435 | AG36: 0.4810977317278073 | AH36: 0.55463347 | AI36: 0.26199262 | AJ36: 0.40659341 | AK36: 0.41935484 | AL36: 0.79279279 | AM36: 0.43558282 | AN36: 0.64130435 | AO36: 6.3691 | AP36: 284.026 | AQ36: 17.899
A37: 43 | B37: 2026-02-26T17:11:32.953489 | C37: deepset/gbert-base | D37: /content/drive/MyDrive/ner_tei/hf_gbert_base | E37: 3e-05 | F37: 0.01 | G37: 16 | H37: 8 | I37: 2 | J37: 400 | K37: 400 | L37: 0.5337802991232594 | M37: /content/drive/MyDrive/ner_tei/43/checkpoint-1600 | N37: 1992 | O37: validation | P37: 0.68901658 | Q37: 0.53369411 | R37: 0.6033876637903484 | S37: 0.3012820512820512 | T37: 0.43838254 | U37: 0.5547445255474452 | V37: 0.7292817679558011 | W37: 0.5857142857142856 | X37: 0.7296137339055793 | Y37: 0.5744798890429959 | Z37: 0.63270777 | AA37: 0.43119266 | AB37: 0.46973865 | AC37: 0.65517241 | AD37: 0.81481481 | AE37: 0.67955801 | AF37: 0.73913043 | AG37: 0.4983156881616939 | AH37: 0.57666463 | AI37: 0.23152709 | AJ37: 0.41095066 | AK37: 0.48101266 | AL37: 0.66 | AM37: 0.51464435 | AN37: 0.72033898 | AO37: 5.0168 | AP37: 302.784 | AQ37: 18.936
A38: 42 | B38: 2026-02-26T17:32:14.778678 | C38: xlm-roberta-base | D38: /content/drive/MyDrive/ner_tei/hf_roberta_base | E38: 1e-05 | F38: 0.01 | G38: 16 | H38: 8 | I38: 2 | J38: 400 | K38: 400 | L38: 0.4879115226337449 | M38: /content/drive/MyDrive/ner_tei/42/checkpoint-2000 | N38: 2000 | O38: test | P38: 0.6298176646232605 | Q38: 0.44972472 | R38: 0.5238393977415308 | S38: 0 | T38: 0.3701375245579568 | U38: 0 | V38: 0.6963562753036436 | W38: 0.4545454545454545 | X38: 0.5604719764011801 | Y38: 0.4677516576250753 | Z38: 0.48265896 | AA38: 0 | AB38: 0.40187713 | AC38: 0 | AD38: 0.63235294 | AE38: 0.52 | AF38: 0.61290323 | AG38: 0.4330357142857143 | AH38: 0.57270233 | AI38: 0 | AJ38: 0.34304443 | AK38: 0 | AL38: 0.77477477 | AM38: 0.40372671 | AN38: 0.51630435 | AO38: 6.236 | AP38: 291.212 | AQ38: 18.281
A39: 42 | B39: 2026-02-26T17:32:14.778678 | C39: xlm-roberta-base | D39: /content/drive/MyDrive/ner_tei/hf_roberta_base | E39: 1e-05 | F39: 0.01 | G39: 16 | H39: 8 | I39: 2 | J39: 400 | K39: 400 | L39: 0.4879115226337449 | M39: /content/drive/MyDrive/ner_tei/42/checkpoint-2000 | N39: 2000 | O39: validation | P39: 0.7010053396224976 | Q39: 0.48791152 | R39: 0.5686274509803921 | S39: 0 | T39: 0.4003990688393748 | U39: 0 | V39: 0.6630434782608696 | W39: 0.4813895781637717 | X39: 0.69107551 | Y39: 0.5266518600777346 | Z39: 0.54146074 | AA39: 0 | AB39: 0.45195195 | AC39: 0 | AD39: 0.71764706 | AE39: 0.59146341 | AF39: 0.755 | AG39: 0.4544801149976042 | AH39: 0.59866424 | AI39: 0 | AJ39: 0.35940299 | AK39: 0 | AL39: 0.61616162 | AM39: 0.40585774 | AN39: 0.6371308 | AO39: 5.5339 | AP39: 274.669 | AQ39: 17.167
A40: 42 | B40: 2026-02-26T17:53:04.480278 | C40: xlm-roberta-base | D40: /content/drive/MyDrive/ner_tei/hf_roberta_base | E40: 2e-05 | F40: 0.01 | G40: 16 | H40: 8 | I40: 2 | J40: 400 | K40: 400 | L40: 0.5239090350338045 | M40: /content/drive/MyDrive/ner_tei/42/checkpoint-2000 | N40: 2000 | O40: test | P40: 0.6233727335929871 | Q40: 0.48405357 | R40: 0.5535314797059764 | S40: 0.2982885085574572 | T40: 0.4019033674963397 | U40: 0.3018867924528302 | V40: 0.6967213114754098 | W40: 0.4605263157894737 | X40: 0.6129032258064515 | Y40: 0.4790926482645531 | Z40: 0.51825254 | AA40: 0.42657343 | AB40: 0.40397351 | AC40: 0.36363636 | AD40: 0.63909774 | AE40: 0.48951049 | AF40: 0.60638298 | AG40: 0.4891183035714285 | AH40: 0.59396433 | AI40: 0.22932331 | AJ40: 0.39985433 | AK40: 0.25806452 | AL40: 0.76576577 | AM40: 0.43478261 | AN40: 0.61956522 | AO40: 6.4893 | AP40: 279.845 | AQ40: 17.567
...

Sheet averages
A1: model_name | B1: seed | C1: f1_average | D1: mean f1 | E1: sd
A2: dbmdz/bert-base-german-cased | B2: 42 | C2: =AVERAGE(combined_metrics!Q2:Q7) -> 0.49953633 | D2: =AVERAGE(C2:C3) -> 0.50050894 | E2: =_xlfn.STDEV.S(combined_metrics!Q2:Q13) -> 0.031152027
A3: dbmdz/bert-base-german-cased | B3: 43 | C3: =AVERAGE(combined_metrics!Q8:Q13) -> 0.50148154
A4: dbmdz/bert-base-german-uncased | B4: 42 | C4: =AVERAGE(combined_metrics!Q14:Q19) -> 0.49854498 | D4: =AVERAGE(C4:C5) -> 0.49713181 | E4: =_xlfn.STDEV.S(combined_metrics!Q14:Q25) -> 0.036257331
A5: dbmdz/bert-base-german-uncased | B5: 43 | C5: =AVERAGE(combined_metrics!Q20:Q25) -> 0.49571865
A6: deepset/gbert-base | B6: 42 | C6: =AVERAGE(combined_metrics!Q26:Q31) -> 0.48588762 | D6: =AVERAGE(C6:C7) -> 0.49253501 | E6: =_xlfn.STDEV.S(combined_metrics!Q26:Q37) -> 0.031010135
A7: deepset/gbert-base | B7: 43 | C7: =AVERAGE(combined_metrics!Q32:Q37) -> 0.49918241
A8: xlm-roberta-base | B8: 42 | C8: =AVERAGE(combined_metrics!Q38:Q43) -> 0.49672216 | D8: =AVERAGE(C8:C9) -> 0.49551878 | E8: =_xlfn.STDEV.S(combined_metrics!Q38:Q49) -> 0.031981226
A9: xlm-roberta-base | B9: 43 | C9: =AVERAGE(combined_metrics!Q44:Q49) -> 0.4943154
A10: xlm-roberta-large | B10: 42 | C10: =AVERAGE(combined_metrics!Q50:Q55) -> 0.50344327 | D10: =AVERAGE(C10:C11) -> 0.51316473 | E10: =_xlfn.STDEV.S(combined_metrics!Q50:Q63) -> 0.028696666
A11: xlm-roberta-large | B11: 43 | C11: =AVERAGE(combined_metrics!Q56:Q61) -> 0.5228862
